1.	Because in main function, it uses throw command without catch block. Thus, the program terminates.
2.	No, after catching a exception, the program will also terminate. The difference between using and not using exception handling is if wee use it, the program will die gracefully.
